Workbook

Sheet Instructions
B2: OCR vs Gemini Spot Check — Home Assessment Extraction
B4: Purpose
B5: Manually verify a sample of fields where Cloud Vision and Gemini disagreed, to (1) confirm Gemini should be the trusted primary extractor and (2) find which columns need mandatory manual review at production scale.
B7: Sample
B8: 30 files total: 20 with the most Cloud Vision/Gemini disagreements ("Bad OCR") + 10 random files, pulled from the 60-file pilot batch. This mixes worst-case failure patterns with a realistic baseline.
B10: How to fill in the 'Spot Check' tab
B11: 1. Open the source PDF for each Source File (pilot_scans_1/2/3 folders).
B12: 2. Read the field directly from the scan and type the true value into the yellow 'Correct Value' column.
B13: 3. Leave 'Correct Value' blank only if the field is genuinely illegible on the scan.
B14: 4. 'Gemini Match?' and 'Cloud Vision Match?' fill in automatically once you type the Correct Value.
B16: How to read the 'Summary by Field' tab
B17: Match rate = % of spot-checked rows where that source's value equals your Correct Value. Any field below the review threshold (cell B2, default 90%) is flagged for mandatory manual review in production.
... B21: - A row here only exists where Cloud Vision and Gemini disagreed — fields where both models already agreed are not in this sample and are assumed correct for this exercise.

Sheet Spot Check
A1: Sample Group | B1: Source File | C1: Section | D1: Field | E1: Cloud Vision Value | F1: Gemini Value | G1: Correct Value (fill in) | H1: Gemini Match? | I1: Cloud Vision Match? | J1: Reviewer Notes
A2: Bad OCR | B2: Sedakhoreni_Sinanyan_-_In_Home_Assessment_10-22-25.pdf | C2: Behavioral Observations | D2: Agitation/Aggression: Does the patient get angry or hostile | F2: Yes | H2: =IF($G2="","",IF(LOWER(TRIM($G2))=LOWER(TRIM($F2)),"Match","Mismatch")) | I2: =IF($G2="","",IF(LOWER(TRIM($G2))=LOWER(TRIM($E2)),"Match","Mismatch"))
A3: Bad OCR | B3: Sedakhoreni_Sinanyan_-_In_Home_Assessment_10-22-25.pdf | C3: Behavioral Observations | D3: Anxiety/Shadowing: Does the patient routinely follow around their caregiver | F3: No | H3: =IF($G3="","",IF(LOWER(TRIM($G3))=LOWER(TRIM($F3)),"Match","Mismatch")) | I3: =IF($G3="","",IF(LOWER(TRIM($G3))=LOWER(TRIM($E3)),"Match","Mismatch"))
A4: Bad OCR | B4: Sedakhoreni_Sinanyan_-_In_Home_Assessment_10-22-25.pdf | C4: Behavioral Observations | D4: Hallucinations: Does the patient see and/or hear things that no one else can see or hear | F4: No | H4: =IF($G4="","",IF(LOWER(TRIM($G4))=LOWER(TRIM($F4)),"Match","Mismatch")) | I4: =IF($G4="","",IF(LOWER(TRIM($G4))=LOWER(TRIM($E4)),"Match","Mismatch"))
A5: Bad OCR | B5: Sedakhoreni_Sinanyan_-_In_Home_Assessment_10-22-25.pdf | C5: Behavioral Observations | D5: Indifference/Social Withdrawal: Does the patient seem less interested in their usual activities | F5: Yes | H5: =IF($G5="","",IF(LOWER(TRIM($G5))=LOWER(TRIM($F5)),"Match","Mismatch")) | I5: =IF($G5="","",IF(LOWER(TRIM($G5))=LOWER(TRIM($E5)),"Match","Mismatch"))
A6: Bad OCR | B6: Sedakhoreni_Sinanyan_-_In_Home_Assessment_10-22-25.pdf | C6: Behavioral Observations | D6: Irritability/Moodiness: Does the patient act impatient | F6: No | H6: =IF($G6="","",IF(LOWER(TRIM($G6))=LOWER(TRIM($F6)),"Match","Mismatch")) | I6: =IF($G6="","",IF(LOWER(TRIM($G6))=LOWER(TRIM($E6)),"Match","Mismatch"))
A7: Bad OCR | B7: Sedakhoreni_Sinanyan_-_In_Home_Assessment_10-22-25.pdf | C7: Behavioral Observations | D7: Other Behavioral Observations | F7: quiet & likes to just sit | H7: =IF($G7="","",IF(LOWER(TRIM($G7))=LOWER(TRIM($F7)),"Match","Mismatch")) | I7: =IF($G7="","",IF(LOWER(TRIM($G7))=LOWER(TRIM($E7)),"Match","Mismatch"))
A8: Bad OCR | B8: Sedakhoreni_Sinanyan_-_In_Home_Assessment_10-22-25.pdf | C8: Behavioral Observations | D8: Sleep Problems: Does the patient have trouble sleeping at night | F8: No | H8: =IF($G8="","",IF(LOWER(TRIM($G8))=LOWER(TRIM($F8)),"Match","Mismatch")) | I8: =IF($G8="","",IF(LOWER(TRIM($G8))=LOWER(TRIM($E8)),"Match","Mismatch"))
A9: Bad OCR | B9: Sedakhoreni_Sinanyan_-_In_Home_Assessment_10-22-25.pdf | C9: Behavioral Observations | D9: Suspiciousness/Paranoia: Is the patient suspicious without good reason | F9: No | H9: =IF($G9="","",IF(LOWER(TRIM($G9))=LOWER(TRIM($F9)),"Match","Mismatch")) | I9: =IF($G9="","",IF(LOWER(TRIM($G9))=LOWER(TRIM($E9)),"Match","Mismatch"))
A10: Bad OCR | B10: Sedakhoreni_Sinanyan_-_In_Home_Assessment_10-22-25.pdf | C10: Daily Function (rating scale) | D10: Bathing | F10: requires_assistance | H10: =IF($G10="","",IF(LOWER(TRIM($G10))=LOWER(TRIM($F10)),"Match","Mismatch")) | I10: =IF($G10="","",IF(LOWER(TRIM($G10))=LOWER(TRIM($E10)),"Match","Mismatch"))
A11: Bad OCR | B11: Sedakhoreni_Sinanyan_-_In_Home_Assessment_10-22-25.pdf | C11: Daily Function (rating scale) | D11: Continence (control of bladder and bowels) | F11: completely_independent | H11: =IF($G11="","",IF(LOWER(TRIM($G11))=LOWER(TRIM($F11)),"Match","Mismatch")) | I11: =IF($G11="","",IF(LOWER(TRIM($G11))=LOWER(TRIM($E11)),"Match","Mismatch"))
A12: Bad OCR | B12: Sedakhoreni_Sinanyan_-_In_Home_Assessment_10-22-25.pdf | C12: Daily Function (rating scale) | D12: Dressing (including getting clothes from drawers or closet) | F12: requires_assistance | H12: =IF($G12="","",IF(LOWER(TRIM($G12))=LOWER(TRIM($F12)),"Match","Mismatch")) | I12: =IF($G12="","",IF(LOWER(TRIM($G12))=LOWER(TRIM($E12)),"Match","Mismatch"))
A13: Bad OCR | B13: Sedakhoreni_Sinanyan_-_In_Home_Assessment_10-22-25.pdf | C13: Daily Function (rating scale) | D13: Driving or using public transportation | F13: cannot_do_at_all | H13: =IF($G13="","",IF(LOWER(TRIM($G13))=LOWER(TRIM($F13)),"Match","Mismatch")) | I13: =IF($G13="","",IF(LOWER(TRIM($G13))=LOWER(TRIM($E13)),"Match","Mismatch"))
... A34: Bad OCR | B34: Sedakhoreni_Sinanyan_-_In_Home_Assessment_10-22-25.pdf | C34: Header / Identifying Info | D34: Date of Birth: | F34: 7/1/1958 | H34: =IF($G34="","",IF(LOWER(TRIM($G34))=LOWER(TRIM($F34)),"Match","Mismatch")) | I34: =IF($G34="","",IF(LOWER(TRIM($G34))=LOWER(TRIM($E34)),"Match","Mismatch"))
A35: Bad OCR | B35: Sedakhoreni_Sinanyan_-_In_Home_Assessment_10-22-25.pdf | C35: Header / Identifying Info | D35: In-Home Assessment Date: | E35: / N ) 14 Are walkways clear of tripping hazards , rugs , cords , and excessive clutter ? ( Y / N ) 15 Is the lighting in the home fairly bright or dim side ? 16 If stairs are accessible , are they free of bright lighting ? ( Y / N ) 17 Is the bathroom equipped with mobility as grab bars , shower chair , toilet riser ? ( Y / 18 Does the patient have access to the kitchen - If kitchen access , which appliance ( s ) is able to use independently ? ( e.g.- microwave toaster / toaster oven , stove top , oven , etc. - If no kitchen access , please include details how patient gets food / drink , how they're restricted , etc. 19 Have safety knobs or an automatic shut - off installed on the stove ? ( Y / N ) 20 Are medications clearly labeled ? ( Y / N ) | F35: 10/22 | H35: =IF($G35="","",IF(LOWER(TRIM($G35))=LOWER(TRIM($F35)),"Match","Mismatch")) | I35: =IF($G35="","",IF(LOWER(TRIM($G35))=LOWER(TRIM($E35)),"Match","Mismatch"))
A36: Bad OCR | B36: Sedakhoreni_Sinanyan_-_In_Home_Assessment_10-22-25.pdf | C36: Header / Identifying Info | D36: Medicare Identification Number: | F36: 1m31f96ch 28 | H36: =IF($G36="","",IF(LOWER(TRIM($G36))=LOWER(TRIM($F36)),"Match","Mismatch")) | I36: =IF($G36="","",IF(LOWER(TRIM($G36))=LOWER(TRIM($E36)),"Match","Mismatch"))
A37: Bad OCR | B37: Sedakhoreni_Sinanyan_-_In_Home_Assessment_10-22-25.pdf | C37: Header / Identifying Info | D37: Name of Patient: | F37: Sedakhoreni Sinanyan | H37: =IF($G37="","",IF(LOWER(TRIM($G37))=LOWER(TRIM($F37)),"Match","Mismatch")) | I37: =IF($G37="","",IF(LOWER(TRIM($G37))=LOWER(TRIM($E37)),"Match","Mismatch"))
A38: Bad OCR | B38: Sedakhoreni_Sinanyan_-_In_Home_Assessment_10-22-25.pdf | C38: Header / Identifying Info | D38: Performed by: | F38: Jyoti Suhag | H38: =IF($G38="","",IF(LOWER(TRIM($G38))=LOWER(TRIM($F38)),"Match","Mismatch")) | I38: =IF($G38="","",IF(LOWER(TRIM($G38))=LOWER(TRIM($E38)),"Match","Mismatch"))
A39: Bad OCR | B39: Sedakhoreni_Sinanyan_-_In_Home_Assessment_10-22-25.pdf | C39: Header / Identifying Info | D39: Referral Date: | F39: 10/7 | H39: =IF($G39="","",IF(LOWER(TRIM($G39))=LOWER(TRIM($F39)),"Match","Mismatch")) | I39: =IF($G39="","",IF(LOWER(TRIM($G39))=LOWER(TRIM($E39)),"Match","Mismatch"))
A40: Bad OCR | B40: In Home Assessment - First Smile -1.pdf | C40: Behavioral Observations | D40: Agitation/Aggression: Does the patient get angry or hostile | E40: Yes | F40: No | H40: =IF($G40="","",IF(LOWER(TRIM($G40))=LOWER(TRIM($F40)),"Match","Mismatch")) | I40: =IF($G40="","",IF(LOWER(TRIM($G40))=LOWER(TRIM($E40)),"Match","Mismatch"))
A41: Bad OCR | B41: In Home Assessment - First Smile -1.pdf | C41: Behavioral Observations | D41: Anxiety/Shadowing: Does the patient routinely follow around their caregiver | F41: No | H41: =IF($G41="","",IF(LOWER(TRIM($G41))=LOWER(TRIM($F41)),"Match","Mismatch")) | I41: =IF($G41="","",IF(LOWER(TRIM($G41))=LOWER(TRIM($E41)),"Match","Mismatch"))
A42: Bad OCR | B42: In Home Assessment - First Smile -1.pdf | C42: Behavioral Observations | D42: Hallucinations: Does the patient see and/or hear things that no one else can see or hear | E42: Yes | F42: No | H42: =IF($G42="","",IF(LOWER(TRIM($G42))=LOWER(TRIM($F42)),"Match","Mismatch")) | I42: =IF($G42="","",IF(LOWER(TRIM($G42))=LOWER(TRIM($E42)),"Match","Mismatch"))
A43: Bad OCR | B43: In Home Assessment - First Smile -1.pdf | C43: Behavioral Observations | D43: Indifference/Social Withdrawal: Does the patient seem less interested in their usual activities | F43: No | H43: =IF($G43="","",IF(LOWER(TRIM($G43))=LOWER(TRIM($F43)),"Match","Mismatch")) | I43: =IF($G43="","",IF(LOWER(TRIM($G43))=LOWER(TRIM($E43)),"Match","Mismatch"))
A44: Bad OCR | B44: In Home Assessment - First Smile -1.pdf | C44: Behavioral Observations | D44: Irritability/Moodiness: Does the patient act impatient | E44: Yes | F44: No | H44: =IF($G44="","",IF(LOWER(TRIM($G44))=LOWER(TRIM($F44)),"Match","Mismatch")) | I44: =IF($G44="","",IF(LOWER(TRIM($G44))=LOWER(TRIM($E44)),"Match","Mismatch"))
A45: Bad OCR | B45: In Home Assessment - First Smile -1.pdf | C45: Behavioral Observations | D45: Sleep Problems: Does the patient have trouble sleeping at night | F45: No | H45: =IF($G45="","",IF(LOWER(TRIM($G45))=LOWER(TRIM($F45)),"Match","Mismatch")) | I45: =IF($G45="","",IF(LOWER(TRIM($G45))=LOWER(TRIM($E45)),"Match","Mismatch"))
A46: Bad OCR | B46: In Home Assessment - First Smile -1.pdf | C46: Behavioral Observations | D46: Suspiciousness/Paranoia: Is the patient suspicious without good reason | E46: Yes | F46: No | H46: =IF($G46="","",IF(LOWER(TRIM($G46))=LOWER(TRIM($F46)),"Match","Mismatch")) | I46: =IF($G46="","",IF(LOWER(TRIM($G46))=LOWER(TRIM($E46)),"Match","Mismatch"))
A47: Bad OCR | B47: In Home Assessment - First Smile -1.pdf | C47: Daily Function (rating scale) | D47: Bathing | F47: completely_independent | H47: =IF($G47="","",IF(LOWER(TRIM($G47))=LOWER(TRIM($F47)),"Match","Mismatch")) | I47: =IF($G47="","",IF(LOWER(TRIM($G47))=LOWER(TRIM($E47)),"Match","Mismatch"))
A48: Bad OCR | B48: In Home Assessment - First Smile -1.pdf | C48: Daily Function (rating scale) | D48: Continence (control of bladder and bowels) | F48: requires_assistance | H48: =IF($G48="","",IF(LOWER(TRIM($G48))=LOWER(TRIM($F48)),"Match","Mismatch")) | I48: =IF($G48="","",IF(LOWER(TRIM($G48))=LOWER(TRIM($E48)),"Match","Mismatch"))
A49: Bad OCR | B49: In Home Assessment - First Smile -1.pdf | C49: Daily Function (rating scale) | D49: Dressing (including getting clothes from drawers or closet) | F49: requires_cueing_or_coaching | H49: =IF($G49="","",IF(LOWER(TRIM($G49))=LOWER(TRIM($F49)),"Match","Mismatch")) | I49: =IF($G49="","",IF(LOWER(TRIM($G49))=LOWER(TRIM($E49)),"Match","Mismatch"))
A50: Bad OCR | B50: In Home Assessment - First Smile -1.pdf | C50: Daily Function (rating scale) | D50: Driving or using public transportation | F50: cannot_do_at_all | H50: =IF($G50="","",IF(LOWER(TRIM($G50))=LOWER(TRIM($F50)),"Match","Mismatch")) | I50: =IF($G50="","",IF(LOWER(TRIM($G50))=LOWER(TRIM($E50)),"Match","Mismatch"))
A51: Bad OCR | B51: In Home Assessment - First Smile -1.pdf | C51: Daily Function (rating scale) | D51: Feeding | F51: requires_assistance | H51: =IF($G51="","",IF(LOWER(TRIM($G51))=LOWER(TRIM($F51)),"Match","Mismatch")) | I51: =IF($G51="","",IF(LOWER(TRIM($G51))=LOWER(TRIM($E51)),"Match","Mismatch"))
A52: Bad OCR | B52: In Home Assessment - First Smile -1.pdf | C52: Daily Function (rating scale) | D52: Finances | F52: cannot_do_at_all | H52: =IF($G52="","",IF(LOWER(TRIM($G52))=LOWER(TRIM($F52)),"Match","Mismatch")) | I52: =IF($G52="","",IF(LOWER(TRIM($G52))=LOWER(TRIM($E52)),"Match","Mismatch"))
A53: Bad OCR | B53: In Home Assessment - First Smile -1.pdf | C53: Daily Function (rating scale) | D53: Food Preparation | F53: cannot_do_at_all | H53: =IF($G53="","",IF(LOWER(TRIM($G53))=LOWER(TRIM($F53)),"Match","Mismatch")) | I53: =IF($G53="","",IF(LOWER(TRIM($G53))=LOWER(TRIM($E53)),"Match","Mismatch"))
A54: Bad OCR | B54: In Home Assessment - First Smile -1.pdf | C54: Daily Function (rating scale) | D54: Grooming (including teeth, hair, shaving, etc.) | F54: requires_assistance | H54: =IF($G54="","",IF(LOWER(TRIM($G54))=LOWER(TRIM($F54)),"Match","Mismatch")) | I54: =IF($G54="","",IF(LOWER(TRIM($G54))=LOWER(TRIM($E54)),"Match","Mismatch"))
A55: Bad OCR | B55: In Home Assessment - First Smile -1.pdf | C55: Daily Function (rating scale) | D55: Housekeeping | F55: cannot_do_at_all | H55: =IF($G55="","",IF(LOWER(TRIM($G55))=LOWER(TRIM($F55)),"Match","Mismatch")) | I55: =IF($G55="","",IF(LOWER(TRIM($G55))=LOWER(TRIM($E55)),"Match","Mismatch"))
A56: Bad OCR | B56: In Home Assessment - First Smile -1.pdf | C56: Daily Function (rating scale) | D56: Laundry | F56: cannot_do_at_all | H56: =IF($G56="","",IF(LOWER(TRIM($G56))=LOWER(TRIM($F56)),"Match","Mismatch")) | I56: =IF($G56="","",IF(LOWER(TRIM($G56))=LOWER(TRIM($E56)),"Match","Mismatch"))
A57: Bad OCR | B57: In Home Assessment - First Smile -1.pdf | C57: Daily Function (rating scale) | D57: Medication Management | F57: cannot_do_at_all | H57: =IF($G57="","",IF(LOWER(TRIM($G57))=LOWER(TRIM($F57)),"Match","Mismatch")) | I57: =IF($G57="","",IF(LOWER(TRIM($G57))=LOWER(TRIM($E57)),"Match","Mismatch"))
A58: Bad OCR | B58: In Home Assessment - First Smile -1.pdf | C58: Daily Function (rating scale) | D58: Shopping | F58: cannot_do_at_all | H58: =IF($G58="","",IF(LOWER(TRIM($G58))=LOWER(TRIM($F58)),"Match","Mismatch")) | I58: =IF($G58="","",IF(LOWER(TRIM($G58))=LOWER(TRIM($E58)),"Match","Mismatch"))
... A61: Bad OCR | B61: In Home Assessment - First Smile -1.pdf | C61: Daily Function (rating scale) | D61: Use the Telephone | F61: requires_cueing_or_coaching | H61: =IF($G61="","",IF(LOWER(TRIM($G61))=LOWER(TRIM($F61)),"Match","Mismatch")) | I61: =IF($G61="","",IF(LOWER(TRIM($G61))=LOWER(TRIM($E61)),"Match","Mismatch"))
A62: Bad OCR | B62: In Home Assessment - First Smile -1.pdf | C62: Environmental / Social | D62: Has the patient fallen in the last year | E62: Yes | F62: No | H62: =IF($G62="","",IF(LOWER(TRIM($G62))=LOWER(TRIM($F62)),"Match","Mismatch")) | I62: =IF($G62="","",IF(LOWER(TRIM($G62))=LOWER(TRIM($E62)),"Match","Mismatch"))
...

Sheet Summary by Field
A1: Mandatory review threshold (Gemini match rate must be ≥ this to skip review): | D1: 0.9
A3: Section | B3: Field | C3: Rows Spot-Checked | D3: Rows Reviewed So Far | E3: Gemini Match Rate | F3: Cloud Vision Match Rate | G3: Mandatory Review?
A4: Behavioral Observations | B4: Agitation/Aggression: Does the patient get angry or hostile | C4: =COUNTIFS('Spot Check'!$C:$C,$A4,'Spot Check'!$D:$D,$B4) -> 16 | D4: =COUNTIFS('Spot Check'!$C:$C,$A4,'Spot Check'!$D:$D,$B4,'Spot Check'!$G:$G,"<>") -> 0 | E4: =IFERROR(COUNTIFS('Spot Check'!$C:$C,$A4,'Spot Check'!$D:$D,$B4,'Spot Check'!$H:$H,"Match")/$D4,"") | F4: =IFERROR(COUNTIFS('Spot Check'!$C:$C,$A4,'Spot Check'!$D:$D,$B4,'Spot Check'!$I:$I,"Match")/$D4,"") | G4: =IF($D4=0,"Not yet reviewed",IF($E4<$D$1,"Yes — below threshold","No")) -> Not yet reviewed
A5: Behavioral Observations | B5: Anxiety/Shadowing: Does the patient routinely follow around their caregiver | C5: =COUNTIFS('Spot Check'!$C:$C,$A5,'Spot Check'!$D:$D,$B5) -> 17 | D5: =COUNTIFS('Spot Check'!$C:$C,$A5,'Spot Check'!$D:$D,$B5,'Spot Check'!$G:$G,"<>") -> 0 | E5: =IFERROR(COUNTIFS('Spot Check'!$C:$C,$A5,'Spot Check'!$D:$D,$B5,'Spot Check'!$H:$H,"Match")/$D5,"") | F5: =IFERROR(COUNTIFS('Spot Check'!$C:$C,$A5,'Spot Check'!$D:$D,$B5,'Spot Check'!$I:$I,"Match")/$D5,"") | G5: =IF($D5=0,"Not yet reviewed",IF($E5<$D$1,"Yes — below threshold","No")) -> Not yet reviewed
A6: Behavioral Observations | B6: Hallucinations: Does the patient see and/or hear things that no one else can see or hear | C6: =COUNTIFS('Spot Check'!$C:$C,$A6,'Spot Check'!$D:$D,$B6) -> 20 | D6: =COUNTIFS('Spot Check'!$C:$C,$A6,'Spot Check'!$D:$D,$B6,'Spot Check'!$G:$G,"<>") -> 0 | E6: =IFERROR(COUNTIFS('Spot Check'!$C:$C,$A6,'Spot Check'!$D:$D,$B6,'Spot Check'!$H:$H,"Match")/$D6,"") | F6: =IFERROR(COUNTIFS('Spot Check'!$C:$C,$A6,'Spot Check'!$D:$D,$B6,'Spot Check'!$I:$I,"Match")/$D6,"") | G6: =IF($D6=0,"Not yet reviewed",IF($E6<$D$1,"Yes — below threshold","No")) -> Not yet reviewed
A7: Behavioral Observations | B7: Indifference/Social Withdrawal: Does the patient seem less interested in their usual activities | C7: =COUNTIFS('Spot Check'!$C:$C,$A7,'Spot Check'!$D:$D,$B7) -> 15 | D7: =COUNTIFS('Spot Check'!$C:$C,$A7,'Spot Check'!$D:$D,$B7,'Spot Check'!$G:$G,"<>") -> 0 | E7: =IFERROR(COUNTIFS('Spot Check'!$C:$C,$A7,'Spot Check'!$D:$D,$B7,'Spot Check'!$H:$H,"Match")/$D7,"") | F7: =IFERROR(COUNTIFS('Spot Check'!$C:$C,$A7,'Spot Check'!$D:$D,$B7,'Spot Check'!$I:$I,"Match")/$D7,"") | G7: =IF($D7=0,"Not yet reviewed",IF($E7<$D$1,"Yes — below threshold","No")) -> Not yet reviewed
A8: Behavioral Observations | B8: Irritability/Moodiness: Does the patient act impatient | C8: =COUNTIFS('Spot Check'!$C:$C,$A8,'Spot Check'!$D:$D,$B8) -> 15 | D8: =COUNTIFS('Spot Check'!$C:$C,$A8,'Spot Check'!$D:$D,$B8,'Spot Check'!$G:$G,"<>") -> 0 | E8: =IFERROR(COUNTIFS('Spot Check'!$C:$C,$A8,'Spot Check'!$D:$D,$B8,'Spot Check'!$H:$H,"Match")/$D8,"") | F8: =IFERROR(COUNTIFS('Spot Check'!$C:$C,$A8,'Spot Check'!$D:$D,$B8,'Spot Check'!$I:$I,"Match")/$D8,"") | G8: =IF($D8=0,"Not yet reviewed",IF($E8<$D$1,"Yes — below threshold","No")) -> Not yet reviewed
A9: Behavioral Observations | B9: Other Behavioral Observations | C9: =COUNTIFS('Spot Check'!$C:$C,$A9,'Spot Check'!$D:$D,$B9) -> 22 | D9: =COUNTIFS('Spot Check'!$C:$C,$A9,'Spot Check'!$D:$D,$B9,'Spot Check'!$G:$G,"<>") -> 0 | E9: =IFERROR(COUNTIFS('Spot Check'!$C:$C,$A9,'Spot Check'!$D:$D,$B9,'Spot Check'!$H:$H,"Match")/$D9,"") | F9: =IFERROR(COUNTIFS('Spot Check'!$C:$C,$A9,'Spot Check'!$D:$D,$B9,'Spot Check'!$I:$I,"Match")/$D9,"") | G9: =IF($D9=0,"Not yet reviewed",IF($E9<$D$1,"Yes — below threshold","No")) -> Not yet reviewed
A10: Behavioral Observations | B10: Sleep Problems: Does the patient have trouble sleeping at night | C10: =COUNTIFS('Spot Check'!$C:$C,$A10,'Spot Check'!$D:$D,$B10) -> 18 | D10: =COUNTIFS('Spot Check'!$C:$C,$A10,'Spot Check'!$D:$D,$B10,'Spot Check'!$G:$G,"<>") -> 0 | E10: =IFERROR(COUNTIFS('Spot Check'!$C:$C,$A10,'Spot Check'!$D:$D,$B10,'Spot Check'!$H:$H,"Match")/$D10,"") | F10: =IFERROR(COUNTIFS('Spot Check'!$C:$C,$A10,'Spot Check'!$D:$D,$B10,'Spot Check'!$I:$I,"Match")/$D10,"") | G10: =IF($D10=0,"Not yet reviewed",IF($E10<$D$1,"Yes — below threshold","No")) -> Not yet reviewed
A11: Behavioral Observations | B11: Suspiciousness/Paranoia: Is the patient suspicious without good reason | C11: =COUNTIFS('Spot Check'!$C:$C,$A11,'Spot Check'!$D:$D,$B11) -> 19 | D11: =COUNTIFS('Spot Check'!$C:$C,$A11,'Spot Check'!$D:$D,$B11,'Spot Check'!$G:$G,"<>") -> 0 | E11: =IFERROR(COUNTIFS('Spot Check'!$C:$C,$A11,'Spot Check'!$D:$D,$B11,'Spot Check'!$H:$H,"Match")/$D11,"") | F11: =IFERROR(COUNTIFS('Spot Check'!$C:$C,$A11,'Spot Check'!$D:$D,$B11,'Spot Check'!$I:$I,"Match")/$D11,"") | G11: =IF($D11=0,"Not yet reviewed",IF($E11<$D$1,"Yes — below threshold","No")) -> Not yet reviewed
A12: Daily Function (rating scale) | B12: Bathing | C12: =COUNTIFS('Spot Check'!$C:$C,$A12,'Spot Check'!$D:$D,$B12) -> 19 | D12: =COUNTIFS('Spot Check'!$C:$C,$A12,'Spot Check'!$D:$D,$B12,'Spot Check'!$G:$G,"<>") -> 0 | E12: =IFERROR(COUNTIFS('Spot Check'!$C:$C,$A12,'Spot Check'!$D:$D,$B12,'Spot Check'!$H:$H,"Match")/$D12,"") | F12: =IFERROR(COUNTIFS('Spot Check'!$C:$C,$A12,'Spot Check'!$D:$D,$B12,'Spot Check'!$I:$I,"Match")/$D12,"") | G12: =IF($D12=0,"Not yet reviewed",IF($E12<$D$1,"Yes — below threshold","No")) -> Not yet reviewed
A13: Daily Function (rating scale) | B13: Continence (control of bladder and bowels) | C13: =COUNTIFS('Spot Check'!$C:$C,$A13,'Spot Check'!$D:$D,$B13) -> 23 | D13: =COUNTIFS('Spot Check'!$C:$C,$A13,'Spot Check'!$D:$D,$B13,'Spot Check'!$G:$G,"<>") -> 0 | E13: =IFERROR(COUNTIFS('Spot Check'!$C:$C,$A13,'Spot Check'!$D:$D,$B13,'Spot Check'!$H:$H,"Match")/$D13,"") | F13: =IFERROR(COUNTIFS('Spot Check'!$C:$C,$A13,'Spot Check'!$D:$D,$B13,'Spot Check'!$I:$I,"Match")/$D13,"") | G13: =IF($D13=0,"Not yet reviewed",IF($E13<$D$1,"Yes — below threshold","No")) -> Not yet reviewed
A14: Daily Function (rating scale) | B14: Dressing (including getting clothes from drawers or closet) | C14: =COUNTIFS('Spot Check'!$C:$C,$A14,'Spot Check'!$D:$D,$B14) -> 20 | D14: =COUNTIFS('Spot Check'!$C:$C,$A14,'Spot Check'!$D:$D,$B14,'Spot Check'!$G:$G,"<>") -> 0 | E14: =IFERROR(COUNTIFS('Spot Check'!$C:$C,$A14,'Spot Check'!$D:$D,$B14,'Spot Check'!$H:$H,"Match")/$D14,"") | F14: =IFERROR(COUNTIFS('Spot Check'!$C:$C,$A14,'Spot Check'!$D:$D,$B14,'Spot Check'!$I:$I,"Match")/$D14,"") | G14: =IF($D14=0,"Not yet reviewed",IF($E14<$D$1,"Yes — below threshold","No")) -> Not yet reviewed
A15: Daily Function (rating scale) | B15: Driving or using public transportation | C15: =COUNTIFS('Spot Check'!$C:$C,$A15,'Spot Check'!$D:$D,$B15) -> 17 | D15: =COUNTIFS('Spot Check'!$C:$C,$A15,'Spot Check'!$D:$D,$B15,'Spot Check'!$G:$G,"<>") -> 0 | E15: =IFERROR(COUNTIFS('Spot Check'!$C:$C,$A15,'Spot Check'!$D:$D,$B15,'Spot Check'!$H:$H,"Match")/$D15,"") | F15: =IFERROR(COUNTIFS('Spot Check'!$C:$C,$A15,'Spot Check'!$D:$D,$B15,'Spot Check'!$I:$I,"Match")/$D15,"") | G15: =IF($D15=0,"Not yet reviewed",IF($E15<$D$1,"Yes — below threshold","No")) -> Not yet reviewed
... A41: Header / Identifying Info | B41: Referral Date: | C41: =COUNTIFS('Spot Check'!$C:$C,$A41,'Spot Check'!$D:$D,$B41) -> 25 | D41: =COUNTIFS('Spot Check'!$C:$C,$A41,'Spot Check'!$D:$D,$B41,'Spot Check'!$G:$G,"<>") -> 0 | E41: =IFERROR(COUNTIFS('Spot Check'!$C:$C,$A41,'Spot Check'!$D:$D,$B41,'Spot Check'!$H:$H,"Match")/$D41,"") | F41: =IFERROR(COUNTIFS('Spot Check'!$C:$C,$A41,'Spot Check'!$D:$D,$B41,'Spot Check'!$I:$I,"Match")/$D41,"") | G41: =IF($D41=0,"Not yet reviewed",IF($E41<$D$1,"Yes — below threshold","No")) -> Not yet reviewed
